<sdf version='1.6'>
  <model name='agrobot_gazebo'>
    <link name='base_footprint'>
      <pose frame=''>0 0 0 0 -0 0</pose>
      <inertial>
        <pose frame=''>-0.007574 0 0.023111 0 -0 0</pose>
        <mass>1.57603</mass>
        <inertia>
          <ixx>0.0137633</ixx>
          <ixy>-4.75766e-05</ixy>
          <ixz>0.000903368</ixz>
          <iyy>0.0147058</iyy>
          <iyz>-3.54223e-06</iyz>
          <izz>0.0187277</izz>
        </inertia>
      </inertial>
      <collision name='base_footprint_fixed_joint_lump__base_link_collision'>
        <pose frame=''>-0.064 0 0.057 0 -0 0</pose>
        <geometry>
          <box>
            <size>0.266 0.266 0.094</size>
          </box>
        </geometry>
      </collision>
      <collision name='base_footprint_fixed_joint_lump__caster_back_left_link_collision_1'>
        <pose frame=''>-0.177 0.064001 0.005 -1.57 0 0</pose>
        <geometry>
          <box>
            <size>0.03 0.009 0.02</size>
          </box>
        </geometry>
      </collision>
      <collision name='base_footprint_fixed_joint_lump__caster_back_right_link_collision_2'>
        <pose frame=''>-0.177 -0.063999 0.005 -1.57 0 0</pose>
        <geometry>
          <box>
            <size>0.03 0.009 0.02</size>
          </box>
        </geometry>
      </collision>
      <collision name='base_footprint_fixed_joint_lump__link1_collision_3'>
        <pose frame=''>-0.1 0 0.096 0 -0 0</pose>
        <geometry>
          <mesh>
            <scale>0.001 0.001 0.001</scale>
            <uri>model://agrobot_description/meshes/chain_link1.stl</uri>
          </mesh>
        </geometry>
      </collision>
      <collision name='base_footprint_fixed_joint_lump__base_scan_collision_4'>
        <pose frame=''>-0.005 0 0.1255 0 -0 0</pose>
        <geometry>
          <cylinder>
            <length>0.0315</length>
            <radius>0.055</radius>
          </cylinder>
        </geometry>
      </collision>
      <visual name='base_footprint_fixed_joint_lump__base_link_visual'>
        <pose frame=''>-0.064 0 0.01 0 -0 0</pose>
        <geometry>
          <mesh>
            <scale>0.001 0.001 0.001</scale>
            <uri>model://agrobot_description/meshes/waffle_pi_base.stl</uri>
          </mesh>
        </geometry>
      </visual>
      <visual name='base_footprint_fixed_joint_lump__link1_visual_1'>
        <pose frame=''>-0.1 0 0.096 0 -0 0</pose>
        <geometry>
          <mesh>
            <scale>0.001 0.001 0.001</scale>
            <uri>model://agrobot_description/meshes/chain_link1.stl</uri>
          </mesh>
        </geometry>
      </visual>
      <visual name='base_footprint_fixed_joint_lump__base_scan_visual_2'>
        <pose frame=''>-0.02 0 0.132 0 -0 0</pose>
        <geometry>
          <mesh>
            <scale>0.001 0.001 0.001</scale>
            <uri>model://agrobot_description/meshes/lds.stl</uri>
          </mesh>
        </geometry>
      </visual>
    </link>
    <link name='link2'>
      <pose frame=''>-0.088 0 0.113 0 -0 0</pose>
      <inertial>
        <pose frame=''>-0.000302 0.00054 0.000474 0 -0 0</pose>
        <mass>0.0984068</mass>
        <inertia>
          <ixx>3.45434e-05</ixx>
          <ixy>-1.60311e-08</ixy>
          <ixz>-3.83752e-07</ixz>
          <iyy>3.26893e-05</iyy>
          <iyz>2.85119e-08</iyz>
          <izz>1.88503e-05</izz>
        </inertia>
      </inertial>
      <collision name='link2_collision'>
        <pose frame=''>0 0 0.019 0 -0 0</pose>
        <geometry>
          <mesh>
            <scale>0.001 0.001 0.001</scale>
            <uri>model://agrobot_description/meshes/chain_link2.stl</uri>
          </mesh>
        </geometry>
      </collision>
      <visual name='link2_visual'>
        <pose frame=''>0 0 0.019 0 -0 0</pose>
        <geometry>
          <mesh>
            <scale>0.001 0.001 0.001</scale>
            <uri>model://agrobot_description/meshes/chain_link2.stl</uri>
          </mesh>
        </geometry>
      </visual>
    </link>
    <joint name='joint1' type='revolute'>
      <child>link2</child>
      <parent>base_footprint</parent>
      <axis>
        <xyz>0 0 1</xyz>
        <limit>
          <lower>-2.82743</lower>
          <upper>2.82743</upper>
          <effort>1</effort>
          <velocity>4.8</velocity>
        </limit>
        <dynamics>
          <spring_reference>0</spring_reference>
          <spring_stiffness>0</spring_stiffness>
        </dynamics>
        <use_parent_model_frame>0</use_parent_model_frame>
      </axis>
    </joint>
    <link name='link3'>
      <pose frame=''>-0.088 0 0.1725 0 -0 0</pose>
      <inertial>
        <pose frame=''>0.010308 0.000377 0.101702 0 -0 0</pose>
        <mass>0.138509</mass>
        <inertia>
          <ixx>0.000330554</ixx>
          <ixy>-9.7941e-08</ixy>
          <ixz>-3.85057e-05</ixz>
          <iyy>0.000342904</iyy>
          <iyz>-1.57175e-06</iyz>
          <izz>6.03465e-05</izz>
        </inertia>
      </inertial>
      <collision name='link3_collision'>
        <pose frame=''>0 0 0 0 -0 0</pose>
        <geometry>
          <mesh>
            <scale>0.001 0.001 0.001</scale>
            <uri>model://agrobot_description/meshes/chain_link3.stl</uri>
          </mesh>
        </geometry>
      </collision>
      <visual name='link3_visual'>
        <pose frame=''>0 0 0 0 -0 0</pose>
        <geometry>
          <mesh>
            <scale>0.001 0.001 0.001</scale>
            <uri>model://agrobot_description/meshes/chain_link3.stl</uri>
          </mesh>
        </geometry>
      </visual>
    </link>
    <joint name='joint2' type='revolute'>
      <child>link3</child>
      <parent>link2</parent>
      <axis>
        <xyz>0 1 0</xyz>
        <limit>
          <lower>-1.79071</lower>
          <upper>1.5708</upper>
          <effort>1</effort>
          <velocity>4.8</velocity>
        </limit>
        <dynamics>
          <spring_reference>0</spring_reference>
          <spring_stiffness>0</spring_stiffness>
        </dynamics>
        <use_parent_model_frame>0</use_parent_model_frame>
      </axis>
    </joint>
    <link name='link4'>
      <pose frame=''>-0.064 0 0.3005 0 -0 0</pose>
      <inertial>
        <pose frame=''>0.09091 0.000389 0.000224 0 -0 0</pose>
        <mass>0.132746</mass>
        <inertia>
          <ixx>3.06542e-05</ixx>
          <ixy>-1.27642e-06</ixy>
          <ixz>-2.68744e-07</ixz>
          <iyy>0.000242303</iyy>
          <iyz>1.15595e-08</iyz>
          <izz>0.000251551</izz>
        </inertia>
      </inertial>
      <collision name='link4_collision'>
        <pose frame=''>0 0 0 0 -0 0</pose>
        <geometry>
          <mesh>
            <scale>0.001 0.001 0.001</scale>
            <uri>model://agrobot_description/meshes/chain_link4.stl</uri>
          </mesh>
        </geometry>
      </collision>
      <visual name='link4_visual'>
        <pose frame=''>0 0 0 0 -0 0</pose>
        <geometry>
          <mesh>
            <scale>0.001 0.001 0.001</scale>
            <uri>model://agrobot_description/meshes/chain_link4.stl</uri>
          </mesh>
        </geometry>
      </visual>
    </link>
    <joint name='joint3' type='revolute'>
      <child>link4</child>
      <parent>link3</parent>
      <axis>
        <xyz>0 1 0</xyz>
        <limit>
          <lower>-0.942478</lower>
          <upper>1.3823</upper>
          <effort>1</effort>
          <velocity>4.8</velocity>
        </limit>
        <dynamics>
          <spring_reference>0</spring_reference>
          <spring_stiffness>0</spring_stiffness>
        </dynamics>
        <use_parent_model_frame>0</use_parent_model_frame>
      </axis>
    </joint>
    <link name='link5'>
      <pose frame=''>0.06 0 0.3005 0 -0 0</pose>
      <inertial>
        <pose frame=''>0.044774 0 0.008852 0 -0 0</pose>
        <mass>0.144276</mass>
        <inertia>
          <ixx>0.00108095</ixx>
          <ixy>2.99238e-11</ixy>
          <ixz>-2.9172e-07</ixz>
          <iyy>0.0010827</iyy>
          <iyz>-3.26124e-12</iyz>
          <izz>0.00109977</izz>
        </inertia>
      </inertial>
      <collision name='link5_collision'>
        <pose frame=''>0 0 0 0 -0 0</pose>
        <geometry>
          <mesh>
            <scale>0.001 0.001 0.001</scale>
            <uri>model://agrobot_description/meshes/chain_link5.stl</uri>
          </mesh>
        </geometry>
      </collision>
      <visual name='link5_visual'>
        <pose frame=''>0 0 0 0 -0 0</pose>
        <geometry>
          <mesh>
            <scale>0.001 0.001 0.001</scale>
            <uri>model://agrobot_description/meshes/chain_link5.stl</uri>
          </mesh>
        </geometry>
      </visual>
      <visual name='link5_fixed_joint_lump__end_effector_link_visual_1'>
        <pose frame=''>0.126 0 0 0 -0 0</pose>
        <geometry>
          <box>
            <size>0.01 0.01 0.01</size>
          </box>
        </geometry>
      </visual>
    </link>
    <joint name='joint4' type='revolute'>
      <child>link5</child>
      <parent>link4</parent>
      <axis>
        <xyz>0 1 0</xyz>
        <limit>
          <lower>-1.79071</lower>
          <upper>2.04204</upper>
          <effort>1</effort>
          <velocity>4.8</velocity>
        </limit>
        <dynamics>
          <spring_reference>0</spring_reference>
          <spring_stiffness>0</spring_stiffness>
        </dynamics>
        <use_parent_model_frame>0</use_parent_model_frame>
      </axis>
    </joint>
    <link name='gripper_link'>
      <pose frame=''>0.1417 0.021 0.3005 0 -0 0</pose>
      <inertial>
        <pose frame=''>0 0 0 0 -0 0</pose>
        <mass>0.001</mass>
        <inertia>
          <ixx>0.001</ixx>
          <ixy>0</ixy>
          <ixz>0</ixz>
          <iyy>0.001</iyy>
          <iyz>0</iyz>
          <izz>0.001</izz>
        </inertia>
      </inertial>
      <collision name='gripper_link_collision'>
        <pose frame=''>0 0 0 0 -0 0</pose>
        <geometry>
          <mesh>
            <scale>0.001 0.001 0.001</scale>
            <uri>model://agrobot_description/meshes/chain_link_grip_l.stl</uri>
          </mesh>
        </geometry>
      </collision>
      <visual name='gripper_link_visual'>
        <pose frame=''>0 0 0 0 -0 0</pose>
        <geometry>
          <mesh>
            <scale>0.001 0.001 0.001</scale>
            <uri>model://agrobot_description/meshes/chain_link_grip_l.stl</uri>
          </mesh>
        </geometry>
      </visual>
    </link>
    <joint name='gripper' type='prismatic'>
      <child>gripper_link</child>
      <parent>link5</parent>
      <axis>
        <xyz>0 1 0</xyz>
        <limit>
          <lower>-0.01</lower>
          <upper>0.019</upper>
          <effort>1</effort>
          <velocity>4.8</velocity>
        </limit>
        <dynamics>
          <spring_reference>0</spring_reference>
          <spring_stiffness>0</spring_stiffness>
        </dynamics>
        <use_parent_model_frame>0</use_parent_model_frame>
      </axis>
    </joint>
    <link name='gripper_link_sub'>
      <pose frame=''>0.1417 -0.021 0.3005 0 -0 0</pose>
      <inertial>
        <pose frame=''>0 0 0 0 -0 0</pose>
        <mass>0.001</mass>
        <inertia>
          <ixx>0.001</ixx>
          <ixy>0</ixy>
          <ixz>0</ixz>
          <iyy>0.001</iyy>
          <iyz>0</iyz>
          <izz>0.001</izz>
        </inertia>
      </inertial>
      <collision name='gripper_link_sub_collision'>
        <pose frame=''>0 -0 0 0 -0 0</pose>
        <geometry>
          <mesh>
            <scale>0.001 0.001 0.001</scale>
            <uri>model://agrobot_description/meshes/chain_link_grip_r.stl</uri>
          </mesh>
        </geometry>
      </collision>
      <visual name='gripper_link_sub_visual'>
        <pose frame=''>0 -0 0 0 -0 0</pose>
        <geometry>
          <mesh>
            <scale>0.001 0.001 0.001</scale>
            <uri>model://agrobot_description/meshes/chain_link_grip_r.stl</uri>
          </mesh>
        </geometry>
      </visual>
    </link>
    <joint name='gripper_sub' type='prismatic'>
      <child>gripper_link_sub</child>
      <parent>link5</parent>
      <axis>
        <xyz>0 -1 0</xyz>
        <limit>
          <lower>-0.01</lower>
          <upper>0.019</upper>
          <effort>1</effort>
          <velocity>4.8</velocity>
        </limit>
        <dynamics>
          <spring_reference>0</spring_reference>
          <spring_stiffness>0</spring_stiffness>
        </dynamics>
        <use_parent_model_frame>0</use_parent_model_frame>
      </axis>
    </joint>
    <link name='wheel_left_link'>
      <pose frame=''>0 0.144 0.033 -1.57 0 0</pose>
      <inertial>
        <pose frame=''>0 0 0 0 -0 0</pose>
        <mass>0.0284989</mass>
        <inertia>
          <ixx>1.11756e-05</ixx>
          <ixy>-4.23698e-11</ixy>
          <ixz>-5.93817e-09</ixz>
          <iyy>1.11924e-05</iyy>
          <iyz>-1.44001e-11</iyz>
          <izz>2.07126e-05</izz>
        </inertia>
      </inertial>
      <collision name='wheel_left_link_collision'>
        <pose frame=''>0 0 0 0 -0 0</pose>
        <geometry>
          <cylinder>
            <length>0.018</length>
            <radius>0.033</radius>
          </cylinder>
        </geometry>
      </collision>
      <visual name='wheel_left_link_visual'>
        <pose frame=''>0 0 0 1.57 -0 0</pose>
        <geometry>
          <mesh>
            <scale>0.001 0.001 0.001</scale>
            <uri>model://agrobot_description/meshes/left_tire.stl</uri>
          </mesh>
        </geometry>
      </visual>
    </link>
    <joint name='wheel_left_joint' type='revolute'>
      <child>wheel_left_link</child>
      <parent>base_footprint</parent>
      <axis>
        <xyz>0 0 1</xyz>
        <limit>
          <lower>-1e+16</lower>
          <upper>1e+16</upper>
        </limit>
        <dynamics>
          <spring_reference>0</spring_reference>
          <spring_stiffness>0</spring_stiffness>
        </dynamics>
        <use_parent_model_frame>0</use_parent_model_frame>
      </axis>
    </joint>
    <link name='wheel_right_link'>
      <pose frame=''>0 -0.144 0.033 -1.57 0 0</pose>
      <inertial>
        <pose frame=''>0 0 0 0 -0 0</pose>
        <mass>0.0284989</mass>
        <inertia>
          <ixx>1.11756e-05</ixx>
          <ixy>-4.23698e-11</ixy>
          <ixz>-5.93817e-09</ixz>
          <iyy>1.11924e-05</iyy>
          <iyz>-1.44001e-11</iyz>
          <izz>2.07126e-05</izz>
        </inertia>
      </inertial>
      <collision name='wheel_right_link_collision'>
        <pose frame=''>0 0 0 0 -0 0</pose>
        <geometry>
          <cylinder>
            <length>0.018</length>
            <radius>0.033</radius>
          </cylinder>
        </geometry>
      </collision>
      <visual name='wheel_right_link_visual'>
        <pose frame=''>0 0 0 1.57 -0 0</pose>
        <geometry>
          <mesh>
            <scale>0.001 0.001 0.001</scale>
            <uri>model://agrobot_description/meshes/right_tire.stl</uri>
          </mesh>
        </geometry>
      </visual>
    </link>
    <joint name='wheel_right_joint' type='revolute'>
      <child>wheel_right_link</child>
      <parent>base_footprint</parent>
      <axis>
        <xyz>0 0 1</xyz>
        <limit>
          <lower>-1e+16</lower>
          <upper>1e+16</upper>
        </limit>
        <dynamics>
          <spring_reference>0</spring_reference>
          <spring_stiffness>0</spring_stiffness>
        </dynamics>
        <use_parent_model_frame>0</use_parent_model_frame>
      </axis>
    </joint>
    <static>0</static>
    <plugin name='gazebo_ros2_control' filename='libgazebo_ros2_control.so'>
      <parameters>$(find agrobot_description)/controllers/controller_om.yaml</parameters>
    </plugin>
    <plugin name='agrobot_diff_drive' filename='libgazebo_ros_diff_drive.so'>
      <ros/>
      <update_rate>30</update_rate>
      <left_joint>wheel_left_joint</left_joint>
      <right_joint>wheel_right_joint</right_joint>
      <wheel_separation>0.287</wheel_separation>
      <wheel_diameter>0.066</wheel_diameter>
      <max_wheel_torque>20</max_wheel_torque>
      <max_wheel_acceleration>1.0</max_wheel_acceleration>
      <command_topic>cmd_vel</command_topic>
      <publish_odom>1</publish_odom>
      <publish_odom_tf>1</publish_odom_tf>
      <publish_wheel_tf>0</publish_wheel_tf>
      <odometry_topic>odom</odometry_topic>
      <odometry_frame>odom</odometry_frame>
      <robot_base_frame>base_footprint</robot_base_frame>
    </plugin>

    <plugin name="agrobot_diff_drive" filename="libgazebo_ros_diff_drive.so">

      <ros>
        <!-- <namespace>/agrobot_diff_drive</namespace> -->
      </ros>

      <update_rate>30</update_rate>

      <!-- wheels -->
      <left_joint>wheel_left_joint</left_joint>
      <right_joint>wheel_right_joint</right_joint>

      <!-- kinematics -->
      <wheel_separation>0.287</wheel_separation>
      <wheel_diameter>0.066</wheel_diameter>

      <!-- limits -->
      <max_wheel_torque>20</max_wheel_torque>
      <max_wheel_acceleration>1.0</max_wheel_acceleration>

      <command_topic>cmd_vel</command_topic>

      <!-- output -->
      <publish_odom>true</publish_odom>
      <publish_odom_tf>true</publish_odom_tf>
      <publish_wheel_tf>false</publish_wheel_tf>

      <odometry_topic>odom</odometry_topic>
      <odometry_frame>odom</odometry_frame>
      <robot_base_frame>base_footprint</robot_base_frame>

    </plugin>
  </model>
</sdf>
